:: loading settings :: url = jar:file:/Users/adhutsav/opt/anaconda3/lib/python3.8/site-packages/pyspark/jars/ivy-2.5.0.jar!/org/apache/ivy/core/settings/ivysettings.xml
ERROR:root:Exception while sending command.
Traceback (most recent call last):
  File "/Users/adhutsav/opt/anaconda3/lib/python3.8/site-packages/pyspark/python/lib/py4j-0.10.9.3-src.zip/py4j/clientserver.py", line 475, in send_command
    answer = smart_decode(self.stream.readline()[:-1])
RuntimeError: reentrant call inside <_io.BufferedReader name=6>

During handling of the above exception, another exception occurred:

Traceback (most recent call last):
  File "/Users/adhutsav/opt/anaconda3/lib/python3.8/site-packages/pyspark/python/lib/py4j-0.10.9.3-src.zip/py4j/java_gateway.py", line 1038, in send_command
    response = connection.send_command(command)
  File "/Users/adhutsav/opt/anaconda3/lib/python3.8/site-packages/pyspark/python/lib/py4j-0.10.9.3-src.zip/py4j/clientserver.py", line 503, in send_command
    raise Py4JNetworkError(
py4j.protocol.Py4JNetworkError: Error while sending or receiving
ERROR:root:Exception while sending command.
Traceback (most recent call last):
  File "/Users/adhutsav/opt/anaconda3/lib/python3.8/site-packages/pyspark/python/lib/py4j-0.10.9.3-src.zip/py4j/clientserver.py", line 475, in send_command
    answer = smart_decode(self.stream.readline()[:-1])
  File "/Users/adhutsav/opt/anaconda3/lib/python3.8/socket.py", line 669, in readinto
    return self._sock.recv_into(b)
  File "/Users/adhutsav/opt/anaconda3/lib/python3.8/site-packages/pyspark/python/lib/pyspark.zip/pyspark/context.py", line 292, in signal_handler
    self.cancelAllJobs()
  File "/Users/adhutsav/opt/anaconda3/lib/python3.8/site-packages/pyspark/python/lib/pyspark.zip/pyspark/context.py", line 1195, in cancelAllJobs
    self._jsc.sc().cancelAllJobs()
  File "/Users/adhutsav/opt/anaconda3/lib/python3.8/site-packages/pyspark/python/lib/py4j-0.10.9.3-src.zip/py4j/java_gateway.py", line 1321, in __call__
    return_value = get_return_value(
  File "/Users/adhutsav/opt/anaconda3/lib/python3.8/site-packages/pyspark/python/lib/pyspark.zip/pyspark/sql/utils.py", line 111, in deco
    return f(*a, **kw)
  File "/Users/adhutsav/opt/anaconda3/lib/python3.8/site-packages/pyspark/python/lib/py4j-0.10.9.3-src.zip/py4j/protocol.py", line 334, in get_return_value
    raise Py4JError(
py4j.protocol.Py4JError: An error occurred while calling o16.sc

During handling of the above exception, another exception occurred:

Traceback (most recent call last):
  File "/Users/adhutsav/opt/anaconda3/lib/python3.8/site-packages/pyspark/python/lib/py4j-0.10.9.3-src.zip/py4j/java_gateway.py", line 1038, in send_command
    response = connection.send_command(command)
  File "/Users/adhutsav/opt/anaconda3/lib/python3.8/site-packages/pyspark/python/lib/py4j-0.10.9.3-src.zip/py4j/clientserver.py", line 503, in send_command
    raise Py4JNetworkError(
py4j.protocol.Py4JNetworkError: Error while sending or receiving
Traceback (most recent call last):
  File "/Users/adhutsav/Desktop/BigData/HW4/newSentiment.py", line 67, in <module>
    sentiment_tweets.writeStream \
  File "/Users/adhutsav/opt/anaconda3/lib/python3.8/site-packages/pyspark/python/lib/pyspark.zip/pyspark/sql/streaming.py", line 101, in awaitTermination
  File "/Users/adhutsav/opt/anaconda3/lib/python3.8/site-packages/pyspark/python/lib/py4j-0.10.9.3-src.zip/py4j/java_gateway.py", line 1321, in __call__
  File "/Users/adhutsav/opt/anaconda3/lib/python3.8/site-packages/pyspark/python/lib/pyspark.zip/pyspark/sql/utils.py", line 111, in deco
  File "/Users/adhutsav/opt/anaconda3/lib/python3.8/site-packages/pyspark/python/lib/py4j-0.10.9.3-src.zip/py4j/protocol.py", line 334, in get_return_value
py4j.protocol.Py4JError: An error occurred while calling o63.awaitTermination
